Workbook

Sheet Guide
D1: A guide to making on-farm tree planting decisions
D5: Background | G5: This section provides background information regarding on-farm tree planting.
D9: Establishment Costs
F10: The costs associated with tree plantations include:
F11: Establishment and maintenance costs for the trees
F12: The opportunity cost of the land that is planted to the trees
F13: Costs to adjacent land that is affected by the trees (see below for more info)
D15: Shelter
F16: Trees can offer valuable shelter to livestock, reducing exposure to harsh weather, lowering energy expenditure, and improving survival rates—particularly for vulnerable animals such as twin-bearing ewes.
F17: The economic benefits of shelter depends on several factors:
F18: Livestock behaviour: Animals do not always seek shelter, so the width and layout of the paddock affect how much protection they receive.
F19: Mob priority and management: Greater benefit is achieved when high-priority mobs (e.g. scanned twin-bearing ewes) are placed in sheltered paddocks. If a farmer does not scan for pregnancy status, shelter is less likely to be targeted where it’s most effective.
F20: Paddock configuration: Narrower or well-oriented paddocks provide better access to tree shelter across the mob.
D22: Adjacent pasture and crop production
F23: Tree belts can influence pasture and crop yields through two competing effects:
F24: Reduced yield near trees due to shading and competition for water and nutrients. Production is reduced by 48% between 2 and 11.2m from the trees.
F25: Increased yield beyond the competition zone due to protection from wind, which reduces plant stress and evaporation. Yield is increased 4% between 16 and 80m from trees.
D27: Carbon sequestration
F28: Planting trees is a method of carbon sequestration. Projects registered under the ACCU Scheme can generate tradable carbon credits (ACCUs). Once generated, you have three management options:
F29: You can sell them, providing an additional revenue stream for your farm and a return on investment.
F30: You can hold them as a future asset.
F31: You can inset them into your farm, meaning that you are using self-generated ACCUs to reduce your farm’s emissions.
F32: Establishing a carbon project incurs costs for monitoring, administration and compliance.
D34: Biodiversity
F35: Tree plantations, particularly those using native species, can significantly enhance on-farm biodiversity. Emerging environmental markets now offer financial incentives and potential income streams for projects that deliver these biodiversity benefits.
F36: The number of credits and the sale price varies a lot by vegetation type and local demand, but past data shows that sites yield often falls around 4–8 credits per hectare and recent sales suggest prices commonly in the order of $2,300–$8,500 per credit
F37: Establishing a carbon project incurs costs for monitoring, administration and compliance.
D39: Biomass production
F40: Above-ground biomass can be harvested and sold to produce clean energy and biofuels, such as diesel, through processes like pyrolysis.
F41: Costs include harvesting, on-farm transport and road transport to the bioenergy plant.
D43: Micro-climate
F44: At the farm scale, trees primarily influence the microclimate through evapotranspiration, which increases local humidity and slightly moderates temperature, and may also contribute to small, localised increases in rainfall
F45: DPIRD is currently undertaking a trial to further investigate the interaction between tree cover and microclimate changes.
F46: It is expected that a substantial area of tree establishment would be required before any measurable microclimate effects translate into on-farm production gains.
D48: Groundwater discharge and salinity
F49: Dryland salinity continues to challenge WA farms, reducing yield and rendering land unproductive. Deep-rooted vegetation draws water from deeper in the soil profile, helping to lower the water table and prevent saline groundwater from rising.
F50: Plantings need to be strategically located, typically targeting recharge areas and valley floors, to maximise their impact on reducing salinity.
F51: Research indicates that substantial revegetation—potentially up to 50% of the catchment—may be required to effectively halt the spread of salinity.
D53: Erosion
F54: Australian soils are prone to erosion, which strips away valuable topsoil and nutrients. Vegetation helps stabilise the soil with their root systems, while their canopies reduce wind and water impact.
...

Sheet Database
A1: Output
B4: Component option | C4: Profit ($/ha of trees)
A5: control | C5: =B24 -> 311234 | E5: =C5 -> 311234
A6: Land opportunity cost | C6: =SUMIFS($F$29:$F$40,$A$29:$A$40,Guide!G245,$B$29:$B$40,Guide!G247,$C$29:$C$40,Guide!G248) -> 169 | E6: =C6 -> 169
A7: +trees | B7: 1 | C7: =Calculations!B19 -> 116.34927 | E7: =C7 -> 116.34927
A8: +livestock shelter | B8: 2 | C8: =SUMIFS($E$70:$E$117,Database!$A$70:$A$117,Guide!$G$245,$B$70:$B$117,Guide!$G$246,$C$70:$C$117,Guide!$G$247,$D$70:$D$117,Guide!$G$248) -> 2 | E8: =C8 -> 2
A9: +adj pad interaction | B9: 3 | C9: =SUMIFS($D$121:$D$136,$A$121:$A$136,Guide!$G$245,$B$121:$B$136,Guide!$G$246,$C$121:$C$136,Guide!$G$247) -> -188.63158 | E9: =C9 -> -188.63158
A10: +carbon | B10: 4 | C10: =Calculations!B54 -> 212.53227 | E10: =C10 -> 212.53227
A11: +biodiversity | B11: 5 | C11: =Calculations!B124 -> -415.23852 | E11: =C11 -> -415.23852
A12: +harvesting | B12: 6 | C12: =Calculations!$B$154 -> 192.88585 | E12: =C12 -> 192.88585
A13: +micro-climate | C13: - | D13: - | E13: =SUMIFS($D$50:$D$51,$A$50:$A$51,Guide!$G$245) -> 8.9025412
A14: +increased grazing | C14: - | D14: - | E14: =SUMIFS($C$59:$C$66,$A$59:$A$66,Guide!$G$245,$B$59:$B$66,Guide!$G$246) -> 4.27054
A15: +reduced salinity spread | C15: =SUMIFS($C$44:$C$45,$A$44:$A$45,Guide!$G$245) -> -3444 | E15: =-C15*E18/Guide!$G$248 -> 3444
D17: Reduction in recharge
A18: Recharge (mm) | B18: 6 | C18: =SUMIFS(INDEX($M$143:$N$4031,0,MATCH(Guide!$G$245,Scenarios!$A$2:$A$3,0)),$B$143:$B$4031,Guide!$G$246,$C$143:$C$4031,Guide!$G$247,$D$143:$D$4031,Guide!$G$248,$E$143:$E$4031,Guide!$J$245,$F$143:$F$4031,Guide!$J$246,$G$143:$G$4031,Guide!$J$247,$H$143:$H$4031,B18) -> 0 | D18: =VLOOKUP(Guide!G245,$A$24:$C$25,3)-C18 -> 16.137 | E18: =D18/VLOOKUP(Guide!G245,$A$24:$C$25,3) -> 1
A22: Control
A23: Location | B23: Farm Profit | C23: Groundwater Recharge (mm)
A24: Central wheatbelt | B24: 311234 | C24: 16.137
A25: Eastern wheatbelt | B25: 299026 | C25: 12.331
A27: Land opp cost
A28: Location | B28: Soil | C28: Area | D28: Farm Profit | E28: Opp cost | F28: Opp cost ($/ha)
A29: Central wheatbelt | B29: Poor | C29: 1 | D29: 311145 | E29: 89 | F29: 89
A30: Central wheatbelt | B30: Poor | C30: 10 | D30: 310336 | E30: 898 | F30: 89.8
A31: Central wheatbelt | B31: Poor | C31: 100 | D31: 301364 | E31: 9870 | F31: 98.7
A32: Central wheatbelt | B32: Good | C32: 1 | D32: 311065 | E32: 169 | F32: 169
A33: Central wheatbelt | B33: Good | C33: 10 | D33: 309537 | E33: 1697 | F33: 169.7
A34: Central wheatbelt | B34: Good | C34: 100 | D34: 294094 | E34: 17140 | F34: 171.4
A35: Eastern wheatbelt | B35: Poor | C35: 1 | D35: 299003 | E35: 23 | F35: 23
A36: Eastern wheatbelt | B36: Poor | C36: 10 | D36: 298796 | E36: 230 | F36: 23
A37: Eastern wheatbelt | B37: Poor | C37: 100 | D37: 296722 | E37: 2304 | F37: 23.04
A38: Eastern wheatbelt | B38: Good | C38: 1 | D38: 298867 | E38: 159 | F38: 159
A39: Eastern wheatbelt | B39: Good | C39: 10 | D39: 297438 | E39: 1588 | F39: 158.8
A40: Eastern wheatbelt | B40: Good | C40: 100 | D40: 282976 | E40: 16050 | F40: 160.5
A42: Salinity spread
A43: Location | B43: Farm Profit | C43: Cost of salinity spread
A44: Central wheatbelt | B44: 307790 | C44: -3444
A45: Eastern wheatbelt | B45: 295088 | C45: -3938
A48: Micro-climate
A49: Location | B49: Farm Profit | C49: Farm Profit Increase | D49: Profit ($/ha of trees)
A50: Central wheatbelt | B50: 353185 | C50: 41951 | D50: 8.9025412
...

Sheet Calculations
A1: Cost
B3: Tree density | C3: Shrub density | F3: Initial Costs - Site Prep | G3: Ripping/Mounding | H3: =Guide!H98 -> 280
A4: Carb Block | B4: 512 | C4: 0 | G4: Initial Weed Control | H4: =Guide!H99 -> 54
A5: Carb Belt | B5: 1000 | C5: 0 | G5: Fertiliser (Base) | H5: =Guide!H100 -> 0
A6: Bio Block | B6: 267 | C6: 300 | G6: Fertiliser (Extra if Harvested) | H6: =Guide!H101 -> 0
A7: Harv Belt | B7: 1000 | C7: 0 | F7: Initial Costs - Planting | G7: Seedlings | H7: =Guide!H102 -> 0.8
G8: Mortality | H8: =Guide!H103 -> 0.1
A9: Planing density | G9: Planting Rate | H9: =Guide!H104 -> 3000
A10: =VLOOKUP(Guide!G246,$A$4:$C$7,2,FALSE)+VLOOKUP(Guide!G246,$A$4:$C$7,3,FALSE) -> 1000 | G10: Planting Equipment | H10: =Guide!H105 -> 300
G11: Farmer Labour (Planting) | H11: =Guide!H106 -> 800
A12: Discount rate | B12: 0.05 | F12: Year 1 Costs | G12: Weed Control | H12: =Guide!H107 -> 10
A13: Project length | B13: 25 | G13: Fertiliser (Base) | H13: =Guide!H108 -> 0
A14: Initial costs (yr 1) | B14: =SUM(H3:H5)+IF(Guide!G246=Calculations!A7,Calculations!H6,0)+A10/(1-H8)*H7+(H10+H11)*((A10/(1-H8))/H9) -> 1630.2963 | G14: Fertiliser (Extra if Harvested) | H14: =Guide!H109 -> 0
A15: Yr2 costs | B15: =SUM(H12:H13)+IF(Guide!G246=Calculations!A7,Calculations!H14,0) -> 10 | F15: Ongoing Costs | G15: Weed Control | H15: =Guide!H110 -> 0
A16: Ongoing costs (>3yr) | B16: =SUM(H15:H16)+IF(Guide!G246=Calculations!A7,H17,0) -> 0 | G16: Fertiliser (Base) | H16: =Guide!H111 -> 0
G17: Fertiliser (Extra if Harvested) | H17: =Guide!H112 -> 0
A18: NPV | B18: {=B14 + B15/(1+$B$12)^1 + SUMPRODUCT(B16/(1+$B$12)^(ROW(INDIRECT("2:"&($B$13-1)))))} -> 1639.8201 | F18: Sequestration Costs | G18: Setup of sequestration monitoring & auditing | H18: =Guide!H113 -> 10000
A19: Annualise the NPV | B19: =B18 * ($B$12 / (1 - (1+$B$12)^-$B$13)) -> 116.34927 | G19: Annual monitoring & auditing of sequestration | H19: =Guide!H114 -> 25
F20: Biodiversity Cost | G20: Setup of biodiversity monitoring & auditing | H20: =Guide!H115 -> 10000
G21: Annual monitoring & auditing of biodiversity | H21: =Guide!H116 -> 25
F22: Harvesting Costs | G22: Contract Cost | H22: =Guide!H117 -> 300
G23: Harvest Rate | H23: =Guide!H118 -> 40
G24: Transport | H24: =Guide!H120 -> 60
A28: Carbon
A29: Risk of reversal buffer | B29: 0.05 | E29: Year | F29: ='[2]Planting config'!$G$13 -> Carbon | G29: ='[2]Planting config'!$H$13 -> Carbon & co-benefits | H29: ='[2]Planting config'!$I$13 -> Biodiversity | I29: ='[2]Planting config'!$J$13 -> Harvested | K29: Year | L29: ='[2]Planting config'!$G$13 -> Carbon | M29: ='[2]Planting config'!$H$13 -> Carbon & co-benefits | N29: ='[2]Planting config'!$I$13 -> Biodiversity | O29: ='[2]Planting config'!$J$13 -> Harvested
A30: Project duration (years) | B30: 25 | E30: 0 | F30: 0 | G30: =F30*1.4 -> 0 | H30: 0 | I30: 0 | K30: 0 | L30: =F30*Guide!H$167/F$56 -> 0 | M30: =G30*Guide!I$167/G$56 -> 0 | N30: =H30*Guide!J$167/H$56 -> 0 | O30: =I30*Guide!K$167/I$56 -> 0
E31: 1 | F31: 904.60832 | G31: 1266.4517 | H31: 901.11027 | I31: 660.31772 | K31: 1 | L31: =F31*Guide!H$167/F$56 -> 905.0906 | M31: =G31*Guide!I$167/G$56 -> 1266.8832 | N31: =H31*Guide!J$167/H$56 -> 900.47885 | O31: =I31*Guide!K$167/I$56 -> 645.13431
A32: Annual monitoring cost ($/ha/yr) | B32: 0 | E32: 2 | F32: 301.17204 | G32: 421.64085 | H32: 67.01672 | I32: 4435.46 | K32: 2 | L32: =F32*Guide!H$167/F$56 -> 301.3326 | M32: =G32*Guide!I$167/G$56 -> 421.78453 | N32: =H32*Guide!J$167/H$56 -> 66.969761 | O32: =I32*Guide!K$167/I$56 -> 4333.4706
A33: Setup cost ($/project) | B33: 0 | E33: 3 | F33: 2044.988 | G33: 2862.9832 | H33: 435.06268 | I33: 13053.774 | K33: 3 | L33: =F33*Guide!H$167/F$56 -> 2046.0783 | M33: =G33*Guide!I$167/G$56 -> 2863.9588 | N33: =H33*Guide!J$167/H$56 -> 434.75782 | O33: =I33*Guide!K$167/I$56 -> 12753.614
A34: Fuel used at t0 | B34: 40 | E34: 4 | F34: 4934.1418 | G34: 6907.7985 | H34: 1463.019 | I34: 17680.035 | K34: 4 | L34: =F34*Guide!H$167/F$56 -> 4936.7723 | M34: =G34*Guide!I$167/G$56 -> 6910.1524 | N34: =H34*Guide!J$167/H$56 -> 1461.9939 | O34: =I34*Guide!K$167/I$56 -> 17273.499
A35: Fuel used in year 1 | B35: 8 | E35: 5 | F35: 7509.7122 | G35: 10513.597 | H35: 2780.338 | I35: 18752.612 | K35: 5 | L35: =F35*Guide!H$167/F$56 -> 7513.7159 | M35: =G35*Guide!I$167/G$56 -> 10517.18 | N35: =H35*Guide!J$167/H$56 -> 2778.3898 | O35: =I35*Guide!K$167/I$56 -> 18321.412
A36: Fuel used in years 2+ | B36: 0 | E36: 6 | F36: 9267.051 | G36: 12973.871 | H36: 3970.4165 | I36: 18198.35 | K36: 6 | L36: =F36*Guide!H$167/F$56 -> 9271.9916 | M36: =G36*Guide!I$167/G$56 -> 12978.292 | N36: =H36*Guide!J$167/H$56 -> 3967.6344 | O36: =I36*Guide!K$167/I$56 -> 17779.895
A37: Fuel CO2 factor (kg CO2e / unit) | B37: 2.7 | E37: 7 | F37: 10283.527 | G37: 14396.938 | H37: 4867.248 | I37: 17043.785 | K37: 7 | L37: =F37*Guide!H$167/F$56 -> 10289.009 | M37: =G37*Guide!I$167/G$56 -> 14401.844 | N37: =H37*Guide!J$167/H$56 -> 4863.8375 | O37: =I37*Guide!K$167/I$56 -> 16651.878
A38: Fuel CH4 factor (kg CO2e / unit) | B38: 0.002123 | E38: 8 | F38: 10762.492 | G38: 15067.488 | H38: 5465.4259 | I38: 15727.245 | K38: 8 | L38: =F38*Guide!H$167/F$56 -> 10768.23 | M38: =G38*Guide!I$167/G$56 -> 15072.623 | N38: =H38*Guide!J$167/H$56 -> 5461.5962 | O38: =I38*Guide!K$167/I$56 -> 15365.611
A39: Fuel N2O factor (kg CO2e / unit) | B39: 0.01351 | E39: 9 | F39: 10882.192 | G39: 15235.069 | H39: 5816.6668 | I39: -46330.213 | K39: 9 | L39: =F39*Guide!H$167/F$56 -> 10887.994 | M39: =G39*Guide!I$167/G$56 -> 15240.261 | N39: =H39*Guide!J$167/H$56 -> 5812.591 | O39: =I39*Guide!K$167/I$56 -> -45264.891
A40: Total fuel factor (kg CO2e / unit) | B40: =SUM(B37:B39) -> 2.715633 | E40: 10 | F40: 10771.241 | G40: 15079.738 | H40: 5981.0237 | I40: 15480.555 | K40: 10 | L40: =F40*Guide!H$167/F$56 -> 10776.984 | M40: =G40*Guide!I$167/G$56 -> 15084.876 | N40: =H40*Guide!J$167/H$56 -> 5976.8328 | O40: =I40*Guide!K$167/I$56 -> 15124.593
A41: Discount rate | B41: =B12 -> 0.05 | E41: 11 | F41: 10516.723 | G41: 14723.413 | H41: 6010.4392 | I41: 15449.357 | K41: 11 | L41: =F41*Guide!H$167/F$56 -> 10522.33 | M41: =G41*Guide!I$167/G$56 -> 14728.43 | N41: =H41*Guide!J$167/H$56 -> 6006.2276 | O41: =I41*Guide!K$167/I$56 -> 15094.113
A42: Include carbon credit flag | B42: =IF(Guide!G250="Included",1,0) -> 1 | E42: 12 | F42: 10176.308 | G42: 14246.831 | H42: 5945.4746 | I42: 15053.402 | K42: 12 | L42: =F42*Guide!H$167/F$56 -> 10181.733 | M42: =G42*Guide!I$167/G$56 -> 14251.686 | N42: =H42*Guide!J$167/H$56 -> 5941.3085 | O42: =I42*Guide!K$167/I$56 -> 14707.262
A43: Carbon price ($/t CO2e) | B43: =HLOOKUP(Guide!J245,Guide!$H$169:$J$170,2) -> 40 | E43: 13 | F43: 9787.9048 | G43: 13703.067 | H43: 5816.404 | I43: 14533.507 | K43: 13 | L43: =F43*Guide!H$167/F$56 -> 9793.123 | M43: =G43*Guide!I$167/G$56 -> 13707.736 | N43: =H43*Guide!J$167/H$56 -> 5812.3284 | O43: =I43*Guide!K$167/I$56 -> 14199.322
E44: 14 | F44: 9376.3499 | G44: 13126.89 | H44: 5645.3202 | I44: 13933.802 | K44: 14 | L44: =F44*Guide!H$167/F$56 -> 9381.3487 | M44: =G44*Guide!I$167/G$56 -> 13131.363 | N44: =H44*Guide!J$167/H$56 -> 5641.3645 | O44: =I44*Guide!K$167/I$56 -> 13613.406
...

Sheet Scenarios
A1: Location | B1: Scenario | C1: Soil | D1: Planting Area (ha) | E1: Carbon credit price | F1: Biodiversity credit price | G1: Biomass price | H1: Components | I1: Micro-climate benefit | J1: Erosion Benefits | K1: Rate of salinity spread
A2: Central wheatbelt | B2: Carb Block | C2: Poor | D2: 1 | E2: Low (-50%) | F2: Low -50% | G2: Low -50% | H2: nil | I2: nil | J2: nil | K2: nil
A3: Eastern wheatbelt | B3: Carb Belt | C3: Good | D3: 10 | E3: Standard | F3: Standard | G3: Standard | H3: Included | I3: Included | J3: Increased summer grazing +500kg/ha | K3: 0.0089
B4: Bio Block | D4: 100 | E4: High (+50%) | F4: Low +50% | G4: Low +50%
B5: Harv Belt
A10: Low -50% | B10: Standard | C10: Low +50%
A11: 0.5 | B11: 1 | C11: 1.5
